Workbook

Sheet nbrain5g
A1: Part ID | B1: Mid X | C1: Mid Y | D1: Layer | E1: Rotation
A2: U4 | B2: -510499 | C2: -11.26 | D2: TOP | E2: -90
A3: U8 | B3: 820303 | C3: -92252 | D3: TOP | E3: -90
A4: U10 | B4: 815185 | C4: 482501 | D4: TOP | E4: -90
A5: UVDATA_IO | B5: -12.68 | C5: 261399 | D5: TOP | E5: -90
A6: R11 | B6: -42.4 | C6: -14.65 | D6: TOP | E6: -90
A7: R12 | B7: -436001 | C7: -14.65 | D7: TOP | E7: -90
A8: R8 | B8: -486499 | C8: -18.7 | D8: TOP | E8: -180
A9: R9 | B9: -510499 | C9: -18.7 | D9: TOP | E9: -180
A10: R10 | B10: -53.45 | C10: -18.7 | D10: TOP | E10: -180
A11: R15 | B11: -446999 | C11: -14.65 | D11: TOP | E11: -270
A12: U15 | B12: -17.1 | C12: 486001 | D12: TOP | E12: 0
A13: U16 | B13: 10.8 | C13: 472001 | D13: TOP | E13: -270
A14: U18 | B14: 2.25 | C14: -379999 | D14: TOP | E14: 0
A15: U20 | B15: 588046 | C15: 116046 | D15: TOP | E15: -180
A16: U21 | B16: 57.55 | C16: -115032 | D16: TOP | E16: -270
A17: R_PUP | B17: 823501 | C17: -15.3 | D17: TOP | E17: -90
A18: R16 | B18: 924499 | C18: -289999 | D18: TOP | E18: -180
A19: R17 | B19: 97.55 | C19: -29.1 | D19: TOP | E19: 0
A20: R18 | B20: 93.85 | C20: -305001 | D20: TOP | E20: 0
A21: R19 | B21: 964499 | C21: -305001 | D21: TOP | E21: -180
A22: C9 | B22: 990999 | C22: -305999 | D22: TOP | E22: 0
A23: C10 | B23: 91.2 | C23: -305001 | D23: TOP | E23: -180
A24: C11 | B24: 964999 | C24: -322001 | D24: TOP | E24: 0
A25: C12 | B25: 937001 | C25: -322001 | D25: TOP | E25: -180
A26: R20 | B26: 926501 | C26: -26.4 | D26: TOP | E26: 0
A27: R21 | B27: 86.95 | C27: -26.4 | D27: TOP | E27: -180
A28: C3 | B28: 870999 | C28: -27.7 | D28: TOP | E28: 0
A29: C4 | B29: 924999 | C29: -27.7 | D29: TOP | E29: -180
A30: R22 | B30: 820499 | C30: -29.1 | D30: TOP | E30: -180
A31: C6 | B31: 883999 | C31: -305001 | D31: TOP | E31: 0
A32: C7 | B32: 807999 | C32: -305999 | D32: TOP | E32: -180
A33: R24 | B33: 833501 | C33: -305999 | D33: TOP | E33: 0
A34: R25 | B34: 85.85 | C34: -305999 | D34: TOP | E34: -180
A35: R23 | B35: 86.95 | C35: -29.1 | D35: TOP | E35: 0
A36: C8 | B36: 85.9 | C36: -322001 | D36: TOP | E36: 0
A37: C13 | B37: 833001 | C37: -322001 | D37: TOP | E37: -180
A38: R5 | B38: 112.31 | C38: 265999 | D38: TOP | E38: -270
A39: R7 | B39: 113.51 | C39: 265999 | D39: TOP | E39: -90
A40: U22 | B40: 106.35 | C40: 658988 | D40: TOP | E40: -90
...

Sheet Φύλλο1
A1: =nbrain5g!A1 -> Part ID | B1: =nbrain5g!B1 -> Mid X | C1: =nbrain5g!C1 -> Mid Y | D1: =nbrain5g!D1 -> Layer | E1: =nbrain5g!E1 -> Rotation
A2: =nbrain5g!A2 -> U4 | B2: =nbrain5g!B2 -> -510499 | C2: =nbrain5g!C2 -> -11.26 | D2: =nbrain5g!D2 -> TOP | E2: =IF(A2<>0,nbrain5g!E2+180,"") -> 90
A3: =nbrain5g!A3 -> U8 | B3: =nbrain5g!B3 -> 820303 | C3: =nbrain5g!C3 -> -92252 | D3: =nbrain5g!D3 -> TOP | E3: =IF(A3<>0,nbrain5g!E3+180,"") -> 90
A4: =nbrain5g!A4 -> U10 | B4: =nbrain5g!B4 -> 815185 | C4: =nbrain5g!C4 -> 482501 | D4: =nbrain5g!D4 -> TOP | E4: =IF(A4<>0,nbrain5g!E4+180,"") -> 90
A5: =nbrain5g!A5 -> UVDATA_IO | B5: =nbrain5g!B5 -> -12.68 | C5: =nbrain5g!C5 -> 261399 | D5: =nbrain5g!D5 -> TOP | E5: =IF(A5<>0,nbrain5g!E5+180,"") -> 90
A6: =nbrain5g!A6 -> R11 | B6: =nbrain5g!B6 -> -42.4 | C6: =nbrain5g!C6 -> -14.65 | D6: =nbrain5g!D6 -> TOP | E6: =IF(A6<>0,nbrain5g!E6+180,"") -> 90
A7: =nbrain5g!A7 -> R12 | B7: =nbrain5g!B7 -> -436001 | C7: =nbrain5g!C7 -> -14.65 | D7: =nbrain5g!D7 -> TOP | E7: =IF(A7<>0,nbrain5g!E7+180,"") -> 90
A8: =nbrain5g!A8 -> R8 | B8: =nbrain5g!B8 -> -486499 | C8: =nbrain5g!C8 -> -18.7 | D8: =nbrain5g!D8 -> TOP | E8: =IF(A8<>0,nbrain5g!E8+180,"") -> 0
A9: =nbrain5g!A9 -> R9 | B9: =nbrain5g!B9 -> -510499 | C9: =nbrain5g!C9 -> -18.7 | D9: =nbrain5g!D9 -> TOP | E9: =IF(A9<>0,nbrain5g!E9+180,"") -> 0
A10: =nbrain5g!A10 -> R10 | B10: =nbrain5g!B10 -> -53.45 | C10: =nbrain5g!C10 -> -18.7 | D10: =nbrain5g!D10 -> TOP | E10: =IF(A10<>0,nbrain5g!E10+180,"") -> 0
A11: =nbrain5g!A11 -> R15 | B11: =nbrain5g!B11 -> -446999 | C11: =nbrain5g!C11 -> -14.65 | D11: =nbrain5g!D11 -> TOP | E11: =IF(A11<>0,nbrain5g!E11+180,"") -> -90
A12: =nbrain5g!A12 -> U15 | B12: =nbrain5g!B12 -> -17.1 | C12: =nbrain5g!C12 -> 486001 | D12: =nbrain5g!D12 -> TOP | E12: =IF(A12<>0,nbrain5g!E12+180,"") -> 180
A13: =nbrain5g!A13 -> U16 | B13: =nbrain5g!B13 -> 10.8 | C13: =nbrain5g!C13 -> 472001 | D13: =nbrain5g!D13 -> TOP | E13: =IF(A13<>0,nbrain5g!E13+180,"") -> -90
... A466: =nbrain5g!A466 -> 0 | B466: =nbrain5g!B466 -> 0 | C466: =nbrain5g!C466 -> 0 | D466: =nbrain5g!D466 -> 0 | E466: =IF(A466<>0,nbrain5g!E466+180,"")
